<?xml version='1.0'?>
<sdf version='1.4'>
	<model name="pallet_jack">
		<static>false</static>

		<!-- CHASSIS -->
		<link name='chassis'>
			<pose>0 0 .1 0 0 0</pose>
			<collision name='collision'>
				<geometry>
					<box>
						<size>1 1 .2</size>
					</box>
				</geometry>
			</collision>

			<visual name='visual'>
				<geometry>
					<box>
						<size>1 1 .2</size>
					</box>
				</geometry>
			</visual>

			<collision name = "front_collision">
				<pose>.55 0 .1 0 0 0</pose>
				<geometry>
					<box>
						<size>.1 .3 .4</size>
					</box>
				</geometry>
			</collision>

			<visual name = "front_visual">
				<pose>.55 0 .1 0 0 0</pose>
				<geometry>
					<box>
						<size>.1 .3 .4</size>
					</box>
				</geometry>
			</visual>

			<collision name = "front_up_collision">
				<pose>.75 0 .25 0 0 0</pose>
				<geometry>
					<box>
						<size>.3 .3 .1</size>
					</box>
				</geometry>
			</collision>

			<visual name = "front_up_visual">
				<pose>.75 0 .25 0 0 0</pose>
				<geometry>
					<box>
						<size>.3 .3 .1</size>
					</box>
				</geometry>
			</visual>

			<sensor type="gpu_ray" name="laser_sensor">
				<pose>.55 0 .35 0 0 3.14</pose>
				<visualize>true</visualize>
				<update_rate>40</update_rate>
				<ray>
					<scan>
						<horizontal>
							<samples>720</samples>
							<resolution>1</resolution>
							<min_angle>-1.570796</min_angle>
							<max_angle>1.570796</max_angle>
						</horizontal>
					</scan>
					<range>
						<min>0.10</min>
						<max>30.0</max>
						<resolution>0.01</resolution>
					</range>
					<noise>
						<type>gaussian</type>
						<!-- Noise parameters based on published spec for Hokuyo laser
						achieving "+-30mm" accuracy at range < 10m.  A mean of 0.0m and
						stddev of 0.01m will put 99.7% of samples within 0.03m of the true
						reading. -->
						<mean>0.0</mean>
						<stddev>0.01</stddev>
					</noise>
				</ray>
				<plugin name="gazebo_ros_head_hokuyo_controller" filename="libgazebo_ros_gpu_laser.so">
					<topicName>/pallet_jack/laser/scan</topicName>
					<frameName>chassis</frameName>
				</plugin>
			</sensor>
		</link>

		<!--LIFT-->
		<link name = "lift">
			<pose> 0 0 .15 0 0 0</pose>
			<collision name='collision'>
				<geometry>
					<box>
						<size>1 1 .05</size>
					</box>
				</geometry>
			</collision>

			<visual name='visual'>
				<geometry>
					<box>
						<size>1 1 .05</size>
					</box>
				</geometry>
			</visual>
		</link>

		<!--BACK LEFT WHEEL-->
		<link name = "back_left_wheel">
			<pose>-.4 -.53 .05 0 1.5707 1.5707</pose>
			<collision name = "back_left_wheel_collision">
				<geometry>
					<cylinder>
						<radius>.1</radius>
						<length>.05</length>
					</cylinder>
				</geometry>
			</collision>

			<visual name = "back_left_wheel_visual">
				<geometry>
					<cylinder>
						<radius>.1</radius>
						<length>.05</length>
					</cylinder>
				</geometry>
			</visual>
		</link>

		<!--BACK RIGHT WHEEL-->
		<link name = "back_right_wheel">
			<pose>-.4 .53 .05 0 1.5707 1.5707</pose>
			<collision name = "back_right_wheel_collision">
				<geometry>
					<cylinder>
						<radius>.1</radius>
						<length>.05</length>
					</cylinder>
				</geometry>
			</collision>

			<visual name = "back_right_wheel_visual">
				<geometry>
					<cylinder>
						<radius>.1</radius>
						<length>.05</length>
					</cylinder>
				</geometry>
			</visual>
		</link>
		<!-- Wheel sources of movement -->

		<!--CENTER RIGHT WHEEL-->
		<link name = "center_right_wheel">
			<pose>.8 .05 .1 0 1.5707 1.5707</pose>
			<collision name = "center_right_wheel_collision">
				<geometry>
					<cylinder>
						<radius>.15</radius>
						<length>.05</length>
					</cylinder>
				</geometry>
			</collision>

			<visual name = "center_right_wheel_visual">
				<geometry>
					<cylinder>
						<radius>.15</radius>
						<length>.05</length>
					</cylinder>
				</geometry>
			</visual>
		</link>

		<!--CENTER LEFT WHEEL-->
		<link name = "center_left_wheel">
			<pose>.8 -.05 .1 0 1.5707 1.5707</pose>
			<collision name = "center_left_wheel_collision">
				<geometry>
					<cylinder>
						<radius>.15</radius>
						<length>.05</length>
					</cylinder>
				</geometry>
			</collision>

			<visual name = "center_left_wheel_visual">
				<geometry>
					<cylinder>
						<radius>.15</radius>
						<length>.05</length>
					</cylinder>
				</geometry>
			</visual>
		</link>

		<!-- this is a dummy link that is used in order to obtain 2 DOF
			 between the chassis and the center wheel -->
		<link name = "dummy_link">
			<pose>.8 0 .1 0 0 0</pose>
			<!--
			<visual name = "dummy">
				<geometry>
					<box>
						<size>.3 .3 .1</size>
					</box>
				</geometry>
			</visual>
			-->
		</link>

		<!--CHASSIS BACK RIGHT WHEEL JOINT-->
		<joint type = "revolute" name = "chassis_backright_joint">
			<pose>0 0 -.1 0 0 0</pose>
			<child>back_right_wheel</child>
			<parent>chassis</parent>
			<axis>
			 	<xyz>0 1 0</xyz>
			</axis>
		</joint>

		<!--CHASSIS BACK LEFT WHEEL JOINT-->
		<joint type = "revolute" name = "chassis_backleft_joint">
			<pose>0 0 -.1 0 0 0</pose>
			<child>back_left_wheel</child>
			<parent>chassis</parent>
			<axis>
			 	<xyz>0 1 0</xyz>
			</axis>
		</joint>

		<!--CHASSIS CENTER WHEEL JOINT-->
		
		<joint type = "revolute" name = "chassis_dummy_joint">
			<pose>0 0 0 0 0 0</pose>
			<child>dummy_link</child>
			<parent>chassis</parent>
			<axis>
				<xyz>0 0 1</xyz>
        		<use_parent_model_frame>0</use_parent_model_frame>
        		<limit>
          			<lower>-1.5707</lower>
          			<upper>1.5707</upper>
        		</limit>
			</axis>
		</joint>

		<!-- JOINTS BETWEEN WHEELS AND DUMMY LINK -->
		<joint type = "revolute" name = "dummy_centerL_joint">
			<pose>0 0 0 0 0 0</pose>
			<child>center_left_wheel</child>
			<parent>dummy_link</parent>
			<axis>
			 	<xyz>0 0 1</xyz>
        		<use_parent_model_frame>0</use_parent_model_frame>

			</axis>
		</joint>

		<joint type = "revolute" name = "dummy_centerR_joint">
			<pose>0 0 0 0 0 0</pose>
			<child>center_right_wheel</child>
			<parent>dummy_link</parent>
			<axis>
			 	<xyz>0 0 1</xyz>
        		<use_parent_model_frame>0</use_parent_model_frame>
			</axis>	
		</joint>

		<!-- JOINT BETWEEN CHASSIS AND LIFT-->
		<joint type = "prismatic" name = "chassis_lift_joint">
			<pose> 0 0 0 0 0 0 </pose>
			<child>lift</child>
			<parent>chassis</parent>
			<axis>
			 	<xyz>0 0 1</xyz>
        		<use_parent_model_frame>0</use_parent_model_frame>
        		<limit>
        			<lower>.02</lower>
        			<upper>1</upper>
        		</limit>
			</axis>	
		</joint>


<!--
		<plugin name="differential_drive_controller" filename="libgazebo_ros_diff_drive.so">
          <alwaysOn>true</alwaysOn>
          <updateRate>10</updateRate>
          <leftJoint>dummy_centerL_joint</leftJoint>
          <rightJoint>dummy_centerR_joint</rightJoint>
          <wheelSeparation>0.1</wheelSeparation>
          <wheelDiameter>0.3</wheelDiameter>
          <wheelTorque>2.5</wheelTorque>
          <torque>5</torque>
          <commandTopic>cmd_vel</commandTopic>
          <odometryTopic>odom</odometryTopic>
          <odometryFrame>odom</odometryFrame>
          <robotBaseFrame>base_footprint</robotBaseFrame>
          <legacyMode>false</legacyMode>
      </plugin>
-->
	</model>
</sdf>